<?xml version='1.0' ?>

<robot name="x80sv" xmlns:xacro="http://www.ros.org/wiki/xacro">
	
	<xacro:include filename="$(find erratic_description)/urdf/erratic_wheel.xacro" />

 <!--
  Wheel inertia:
   Assuming solid cylinder:
   Izz = (1/2)*m*r^2
   Ixx = Iyy = (1/12)*m*(3*r^2 + h^2)
   Using m = 0.05 [kg] (wheel weight 50 gr.)
   r = 0.05 [m] (wheel radius)
   h = 0.01 [m] (wheel width)
   Ixx = Iyy = 3.17e-5
   Izz = 6.25e-5
-->
<xacro:property name="wheel_base" value="0.2" />
<xacro:property name="wheel_diameter" value="0.16" />
<xacro:property name="wheel_distance" value="0.305"/>
<xacro:property name="axis_height" value="0.05" />
<xacro:property name="wheel_mass" value="0.05" />
<xacro:property name="wheel_Ixx" value="0.0000317" />
<xacro:property name="wheel_Izz" value="0.0000625" />
<xacro:property name="M_PI" value="3.141592653589793238462643383279502884197169399375105820974944592307816406" />


 	<link name="base_footprint">
		<inertial>
			<mass value="0.0001" />
			<origin xyz="0 0 0" />
			<inertia ixx="0.0001" ixy="0.0" ixz="0.0"
				iyy="0.0001" iyz="0.0" 
				izz="0.0001" />
		</inertial>

		<visual>
			<origin xyz="0 0 0" rpy="0 0 0" />
			<geometry>
				<box size="0.001 0.001 0.001" />
			</geometry>
			<material name="Green" />
		</visual>

		<collision>
			<origin xyz="0 0 0.128" rpy="0 0 0" />
			<geometry>
				<box size="0.001 0.001 0.001" />
			</geometry>
		</collision>
	</link>

	<joint name="base_footprint_joint" type="fixed">
		<origin xyz="0.063 0 0.128" rpy="0 0 0" />
		<parent link="base_footprint"/>
		<child link="base_link" />
	</joint>


	<link name="base_link">
		<collision>
			<origin xyz="0 0 0" rpy="0 0 0"/>
			<geometry>
				<box size="0.4 0.2 0.01" />
			</geometry>
		</collision>
		<visual>
			<origin xyz="0 0 -0.20" rpy="0 0 0"/>
			<geometry>
				<mesh filename="package://x80sv_description/meshes/x80sv.stl" />
			</geometry>
		</visual>
		<inertial>
			<mass value="0.2" />
			<origin xyz="0 0 0" />
			<inertia ixx="1.0" ixy="0.0" ixz="0.0"
				iyy="1.0" iyz="0.0" 
				izz="1.0" />
		</inertial>
	</link>


	<joint name="base_caster_support_joint" type="continuous">
		<origin xyz="-0.188 0 -0.043" rpy="0 0 0" />
		<parent link="base_link" />
		<child link="base_caster_support_link"/>

		<axis xyz="0 0 1" />
		<anchor xyz="0.01 0 0" />
		<limit effort="100" velocity="100" k_velocity="0" />
		<joint_properties damping="0.0" friction="0.0" />
	</joint>

	<transmission type="pr2_mechanism_model/SimpleTransmission" name="base_caster_support_trans">
		<actuator name="base_caster_support_motor" />
		<joint name="base_caster_support_joint" />
		<mechanicalReduction>1.0</mechanicalReduction>
	</transmission>

	<link name="base_caster_support_link">
		<inertial>
			<mass value="0.1"/>
			<origin xyz="0 0 0" />
			<inertia ixx="0.01" ixy="0.0" ixz="0.0"
				iyy="0.01" iyz="0.0"
				izz="0.01" />
		</inertial>

		<visual>
			<origin xyz="0 0 -0.08" rpy="0 0 0" />
			<geometry>
				<mesh filename="package://erratic_description/meshes/collada/erratic_caster_support_link.dae"/>
			</geometry>
		</visual>

		<collision>
			<origin xyz="0 0 0" rpy="0 0 0" />
			<geometry>
				<mesh filename="package://erratic_description/meshes/collada/erratic_caster_support_link.dae"/>
			</geometry>
		</collision>
	</link>	

	<joint name="caster_wheel_joint" type="continuous">
		<origin xyz="-0.025 0 -0.1229" rpy="0 0 0" />
		<parent link="base_caster_support_link" />
		<child link="caster_wheel_link" />

		<axis xyz="0 1 0" />
		<anchor xyz="0 0 0" />
		<limit effort="100" velocity="100" k_velocity="0" />
		<joint_properties damping="0.0" friction="0.0" />
	</joint>

	<transmission type="pr2_mechanism_model/SimpleTransmission" name="caster_wheel_trans">
		<actuator name="caster_wheel_motor" />
		<joint name="caster_wheel_joint" />
		<mechanicalReduction>1.0</mechanicalReduction>
	</transmission>

	<link name="caster_wheel_link">
		<inertial>
			<mass value="0.1" /> 
			<origin xyz="0 0 0" rpy="0 0 0" />
			<inertia  ixx="0.012411765597" ixy="-0.000711733678" ixz="0.00050272983"
				iyy="0.015218160428" iyz="-0.000004273467"
				izz="0.011763977943" />
			</inertial>

			<visual>
				<origin xyz="0 0 0" rpy="0 0 0" />
				<geometry>
					<mesh filename="package://erratic_description/meshes/collada/erratic_caster_wheel_link.dae"/>
				</geometry>
				<material name="Black"/>
			</visual>

			<collision>
				<origin xyz="0 0 0" rpy="0 0 0" />
				<geometry>
					<mesh filename="package://erratic_description/meshes/collada/erratic_caster_wheel_link.dae"/>
				</geometry>
			</collision>
		</link>

	<gazebo reference="caster_wheel_link">
		<mu1 value="100.0" />
		<mu2 value="100.0" />
		<kp  value="1000000.0" />
		<kd  value="1.0" />
	</gazebo>


	<erratic_wheel suffix="left" parent="base_link">
		<origin xyz="0.0 0.15525 -0.129" rpy="0 0 0" />
	</erratic_wheel>

	<erratic_wheel suffix="right" parent="base_link">
		<origin xyz="0.0 -0.15525 -0.129" rpy="0 0 0" />
	</erratic_wheel>




 <link name="laser_scanner">
  <collision>
   <origin xyz="0 0 0" rpy="0 0 0"/>
   <geometry><cylinder radius="0.07" length="0.01" /></geometry>
  </collision>
  <visual>
   <origin xyz="0 0 0" rpy="0 0 0"/>
   <geometry><cylinder radius="0.07" length="0.01" /></geometry>
  </visual>
  <inertial>
   <mass value="0.1" />
   <inertia ixx="0.0001" ixy="0" ixz="0" iyy="0.0001" iyz="0" izz="0.0001" />
  </inertial>
 </link>

  <joint type="fixed" name="laser_scanner_glue">
   <origin xyz="0 0 0.05" rpy="0 0 0"/>
  <child link="laser_scanner"/>
  <parent link="base_link" />
  </joint>


<!-- plugins -->

<!-- hokuyo -->
   <gazebo reference="laser_scanner">
    <sensor type="ray" name="laser_scanner_sensor">
      <pose>0 0 0 0 0 0</pose>
      <visualize>true</visualize>
      <update_rate>10</update_rate>
      <ray>
        <scan>
          <horizontal>
            <samples>360</samples>
            <resolution>1</resolution>
            <min_angle>${0.5*M_PI}</min_angle>
            <max_angle>${2.5*M_PI}</max_angle>
          </horizontal>
        </scan>
        <range>
          <min>0.20</min>
          <max>4.0</max>
          <resolution>0.01</resolution>
        </range>
        <noise>
          <type>gaussian</type>
          <mean>0.0</mean>
          <stddev>0.01</stddev>
        </noise>
      </ray>
      <plugin name="gazebo_ros_head_hokuyo_controller" filename="libgazebo_ros_laser.so">
        <topicName>/laser/scan</topicName>
        <frameName>laser_scanner</frameName>
      </plugin>
    </sensor>
   </gazebo>
   
<gazebo>
	<plugin name="differential_drive_controller" filename="libgazebo_ros_diff_drive.so">
		<alwaysOn>true</alwaysOn>
		<updateRate>100</updateRate>
		<leftJoint>base_link_right_wheel_joint</leftJoint>
		<rightJoint>base_link_left_wheel_joint</rightJoint>
		<wheelSeparation>${wheel_distance}</wheelSeparation>
		<wheelDiameter>${wheel_diameter}</wheelDiameter>
		<torque>5</torque>
		<commandTopic>cmd_vel</commandTopic>
		<odometryTopic>odom</odometryTopic>
		<odometryFrame>odom</odometryFrame>
		<robotBaseFrame>base_footprint</robotBaseFrame>
	</plugin>

</gazebo>

</robot>

